Workbook

Sheet CÀLCUL QUANTITATS VOLUM
A1: CÀLCUL QUANTITATS PER VOLUM | K1: CÀRREGA MÀQUINA | P1: KPM 800 MAX - Neteja partícules | R1: REQUERIMENTS SUPERFÍCIALS | X1: KPM 800 MAX - Neteja partícules
P3: =SUMIF(I11:I1048576,X1,Q11:Q1048576) -> 1.1295883 | X3: =SUMIF(I11:I1048576,X1,Q11:Q1048576) -> 1.1295883
R8: DESENGREIX | S8: NETEJA | W8: OLIAT
A9: INFO COMERCIAL | D9: CARACTERÍSTIQUES FÍSIQUES PEÇA | K9: PRODUCTIVITAT | R9: N·m-1 | S9: Mida partícula (µm) | V9: Gravimetria | X9: Comentari
A10: Oferta | B10: Ref | C10: Volum anual | D10: a(mm) | E10: b(mm) | F10: h(mm) | G10: Pes net peça (kg) | H10: V(mm3) | I10: Màquina/Embalatge | J10: Coef. Seguretat | K10: Qtt per gàbia teòric | L10: Pes per cicle teoric (kg) | M10: Pes per cicle real ( kg ) | N10: Qtt real per gàbia real | O10: Qtt per cicle | P10: Prod/h real | Q10: Capacitat màquina | R10: Tensió superficial | S10: Hard Metallic | T10: Hard Non-Metallic | U10: Fibres | V10: Residu en mg/100g peça | W10: SI/NO | Y10: HORES | Z10: Estalvi h | AA10: € MOD
A11: 092/21 | B11: A014Y303 | C11: 386642 | D11: 95 | E11: 105 | F11: 17 | G11: 0.08843 | H11: =F11*E11*D11 -> 169575 | I11: Màquina perclor ( VAIOC ) | J11: 0.7 | K11: =IFERROR((VLOOKUP(I11,'DADES VOLUMS'!$A$3:$J$1005,5,FALSE))/('CÀLCUL QUANTITATS VOLUM'!H11)*('CÀLCUL QUANTITATS VOLUM'!J11),"") -> 743.03406 | L11: =IFERROR(G11*K11*VLOOKUP(I11,'DADES VOLUMS'!$A$3:$J$1005,6,FALSE),"") -> 65.706502 | M11: =IFERROR(IF(L11>VLOOKUP(I11,'DADES VOLUMS'!$A$3:$J$1005,9,FALSE),VLOOKUP(I11,'DADES VOLUMS'!$A$3:$J$1005,9,FALSE),L11),"") -> 65.706502 | N11: =IFERROR(K11*M11/L11,"") -> 743.03406 | O11: =IFERROR(N11*VLOOKUP(I11,'DADES VOLUMS'!$A$3:$J$1005,6,FALSE),"") -> 743.03406 | P11: =IFERROR(O11*VLOOKUP(I11,'DADES VOLUMS'!$A$3:$J$1005,8,FALSE),"") -> 3715.1703 | Q11: =IFERROR(C11/P11/5400,"") -> 0.019272433
B12: A014Y303 | C12: 386642 | D12: 95 | E12: 105 | F12: 29.5 | G12: 0.08843 | H12: =F12*E12*D12 -> 294262.5 | I12: Màquina perclor ( VAIOC ) | J12: 0.7 | K12: =IFERROR((VLOOKUP(I12,'DADES VOLUMS'!$A$3:$J$1005,5,FALSE))/('CÀLCUL QUANTITATS VOLUM'!H12)*('CÀLCUL QUANTITATS VOLUM'!J12),"") -> 428.18912 | L12: =IFERROR(G12*K12*VLOOKUP(I12,'DADES VOLUMS'!$A$3:$J$1005,6,FALSE),"") -> 37.864764 | M12: =IFERROR(IF(L12>VLOOKUP(I12,'DADES VOLUMS'!$A$3:$J$1005,9,FALSE),VLOOKUP(I12,'DADES VOLUMS'!$A$3:$J$1005,9,FALSE),L12),"") -> 37.864764 | N12: =IFERROR(K12*M12/L12,"") -> 428.18912 | O12: =IFERROR(N12*VLOOKUP(I12,'DADES VOLUMS'!$A$3:$J$1005,6,FALSE),"") -> 428.18912 | P12: =IFERROR(O12*VLOOKUP(I12,'DADES VOLUMS'!$A$3:$J$1005,8,FALSE),"") -> 2140.9456 | Q12: =IFERROR(C12/P12/5400,"") -> 0.03344334
A13: 141/21 | B13: 6411574 | C13: 1100000 | D13: 75 | E13: 77 | F13: 20 | G13: 0.05122 | H13: =F13*E13*D13 -> 115500 | I13: Màquina perclor ( VAIOC ) | J13: 0.7 | K13: =IFERROR((VLOOKUP(I13,'DADES VOLUMS'!$A$3:$J$1005,5,FALSE))/('CÀLCUL QUANTITATS VOLUM'!H13)*('CÀLCUL QUANTITATS VOLUM'!J13),"") -> 1090.9091 | L13: =IFERROR(G13*K13*VLOOKUP(I13,'DADES VOLUMS'!$A$3:$J$1005,6,FALSE),"") -> 55.876364 | M13: =IFERROR(IF(L13>VLOOKUP(I13,'DADES VOLUMS'!$A$3:$J$1005,9,FALSE),VLOOKUP(I13,'DADES VOLUMS'!$A$3:$J$1005,9,FALSE),L13),"") -> 55.876364 | N13: =IFERROR(K13*M13/L13,"") -> 1090.9091 | O13: =IFERROR(N13*VLOOKUP(I13,'DADES VOLUMS'!$A$3:$J$1005,6,FALSE),"") -> 1090.9091 | P13: =IFERROR(O13*VLOOKUP(I13,'DADES VOLUMS'!$A$3:$J$1005,8,FALSE),"") -> 5454.5455 | Q13: =IFERROR(C13/P13/5400,"") -> 0.037345679
B14: 51006731 | D14: 151 | E14: 54.8 | F14: 26.3 | G14: 0.1 | H14: =F14*E14*D14 -> 217627.24 | I14: Màquina perclor ( VAIOC ) | K14: =IFERROR((VLOOKUP(I14,'DADES VOLUMS'!$A$3:$J$1005,5,FALSE))/('CÀLCUL QUANTITATS VOLUM'!H14)*('CÀLCUL QUANTITATS VOLUM'!J14),"") -> 0 | L14: =IFERROR(G14*K14*VLOOKUP(I14,'DADES VOLUMS'!$A$3:$J$1005,6,FALSE),"") -> 0 | M14: =IFERROR(IF(L14>VLOOKUP(I14,'DADES VOLUMS'!$A$3:$J$1005,9,FALSE),VLOOKUP(I14,'DADES VOLUMS'!$A$3:$J$1005,9,FALSE),L14),"") -> 0 | N14: =IFERROR(K14*M14/L14,"") | O14: =IFERROR(N14*VLOOKUP(I14,'DADES VOLUMS'!$A$3:$J$1005,6,FALSE),"") | P14: =IFERROR(O14*VLOOKUP(I14,'DADES VOLUMS'!$A$3:$J$1005,8,FALSE),"") | Q14: =IFERROR(C14/P14/5400,"")
B15: 51006729 | D15: 187.9 | E15: 109.5 | F15: 30 | G15: 0.239 | H15: =F15*E15*D15 -> 617251.5 | I15: Màquina perclor ( VAIOC ) | K15: =IFERROR((VLOOKUP(I15,'DADES VOLUMS'!$A$3:$J$1005,5,FALSE))/('CÀLCUL QUANTITATS VOLUM'!H15)*('CÀLCUL QUANTITATS VOLUM'!J15),"") -> 0 | L15: =IFERROR(G15*K15*VLOOKUP(I15,'DADES VOLUMS'!$A$3:$J$1005,6,FALSE),"") -> 0 | M15: =IFERROR(IF(L15>VLOOKUP(I15,'DADES VOLUMS'!$A$3:$J$1005,9,FALSE),VLOOKUP(I15,'DADES VOLUMS'!$A$3:$J$1005,9,FALSE),L15),"") -> 0 | N15: =IFERROR(K15*M15/L15,"") | O15: =IFERROR(N15*VLOOKUP(I15,'DADES VOLUMS'!$A$3:$J$1005,6,FALSE),"") | P15: =IFERROR(O15*VLOOKUP(I15,'DADES VOLUMS'!$A$3:$J$1005,8,FALSE),"") | Q15: =IFERROR(C15/P15/5400,"")
B16: 51006612 | D16: 184 | E16: 103 | F16: 52.48 | G16: 0.205 | H16: =F16*E16*D16 -> 994600.96 | I16: Màquina perclor ( VAIOC ) | K16: =IFERROR((VLOOKUP(I16,'DADES VOLUMS'!$A$3:$J$1005,5,FALSE))/('CÀLCUL QUANTITATS VOLUM'!H16)*('CÀLCUL QUANTITATS VOLUM'!J16),"") -> 0 | L16: =IFERROR(G16*K16*VLOOKUP(I16,'DADES VOLUMS'!$A$3:$J$1005,6,FALSE),"") -> 0 | M16: =IFERROR(IF(L16>VLOOKUP(I16,'DADES VOLUMS'!$A$3:$J$1005,9,FALSE),VLOOKUP(I16,'DADES VOLUMS'!$A$3:$J$1005,9,FALSE),L16),"") -> 0 | N16: =IFERROR(K16*M16/L16,"") | O16: =IFERROR(N16*VLOOKUP(I16,'DADES VOLUMS'!$A$3:$J$1005,6,FALSE),"") | P16: =IFERROR(O16*VLOOKUP(I16,'DADES VOLUMS'!$A$3:$J$1005,8,FALSE),"") | Q16: =IFERROR(C16/P16/5400,"")
B17: 51006406 | D17: 135 | E17: 85.95 | F17: 85.5 | G17: 0.21 | H17: =F17*E17*D17 -> 992077.88 | I17: Màquina perclor ( VAIOC ) | K17: =IFERROR((VLOOKUP(I17,'DADES VOLUMS'!$A$3:$J$1005,5,FALSE))/('CÀLCUL QUANTITATS VOLUM'!H17)*('CÀLCUL QUANTITATS VOLUM'!J17),"") -> 0 | L17: =IFERROR(G17*K17*VLOOKUP(I17,'DADES VOLUMS'!$A$3:$J$1005,6,FALSE),"") -> 0 | M17: =IFERROR(IF(L17>VLOOKUP(I17,'DADES VOLUMS'!$A$3:$J$1005,9,FALSE),VLOOKUP(I17,'DADES VOLUMS'!$A$3:$J$1005,9,FALSE),L17),"") -> 0 | N17: =IFERROR(K17*M17/L17,"") | O17: =IFERROR(N17*VLOOKUP(I17,'DADES VOLUMS'!$A$3:$J$1005,6,FALSE),"") | P17: =IFERROR(O17*VLOOKUP(I17,'DADES VOLUMS'!$A$3:$J$1005,8,FALSE),"") | Q17: =IFERROR(C17/P17/5400,"")
B18: 51006224 | D18: 267.5 | E18: 53 | F18: 30 | G18: 0.082 | H18: =F18*E18*D18 -> 425325 | I18: Màquina perclor ( VAIOC ) | K18: =IFERROR((VLOOKUP(I18,'DADES VOLUMS'!$A$3:$J$1005,5,FALSE))/('CÀLCUL QUANTITATS VOLUM'!H18)*('CÀLCUL QUANTITATS VOLUM'!J18),"") -> 0 | L18: =IFERROR(G18*K18*VLOOKUP(I18,'DADES VOLUMS'!$A$3:$J$1005,6,FALSE),"") -> 0 | M18: =IFERROR(IF(L18>VLOOKUP(I18,'DADES VOLUMS'!$A$3:$J$1005,9,FALSE),VLOOKUP(I18,'DADES VOLUMS'!$A$3:$J$1005,9,FALSE),L18),"") -> 0 | N18: =IFERROR(K18*M18/L18,"") | O18: =IFERROR(N18*VLOOKUP(I18,'DADES VOLUMS'!$A$3:$J$1005,6,FALSE),"") | P18: =IFERROR(O18*VLOOKUP(I18,'DADES VOLUMS'!$A$3:$J$1005,8,FALSE),"") | Q18: =IFERROR(C18/P18/5400,"")
B19: 51005674 | D19: 250 | E19: 32 | F19: 38 | G19: 0.11 | H19: =F19*E19*D19 -> 304000 | I19: Màquina perclor ( VAIOC ) | K19: =IFERROR((VLOOKUP(I19,'DADES VOLUMS'!$A$3:$J$1005,5,FALSE))/('CÀLCUL QUANTITATS VOLUM'!H19)*('CÀLCUL QUANTITATS VOLUM'!J19),"") -> 0 | L19: =IFERROR(G19*K19*VLOOKUP(I19,'DADES VOLUMS'!$A$3:$J$1005,6,FALSE),"") -> 0 | M19: =IFERROR(IF(L19>VLOOKUP(I19,'DADES VOLUMS'!$A$3:$J$1005,9,FALSE),VLOOKUP(I19,'DADES VOLUMS'!$A$3:$J$1005,9,FALSE),L19),"") -> 0 | N19: =IFERROR(K19*M19/L19,"") | O19: =IFERROR(N19*VLOOKUP(I19,'DADES VOLUMS'!$A$3:$J$1005,6,FALSE),"") | P19: =IFERROR(O19*VLOOKUP(I19,'DADES VOLUMS'!$A$3:$J$1005,8,FALSE),"") | Q19: =IFERROR(C19/P19/5400,"")
B20: 51000675 | D20: 206 | E20: 52.3 | F20: 17.1 | G20: 0.064 | H20: =F20*E20*D20 -> 184231.98 | I20: Màquina perclor ( VAIOC ) | K20: =IFERROR((VLOOKUP(I20,'DADES VOLUMS'!$A$3:$J$1005,5,FALSE))/('CÀLCUL QUANTITATS VOLUM'!H20)*('CÀLCUL QUANTITATS VOLUM'!J20),"") -> 0 | L20: =IFERROR(G20*K20*VLOOKUP(I20,'DADES VOLUMS'!$A$3:$J$1005,6,FALSE),"") -> 0 | M20: =IFERROR(IF(L20>VLOOKUP(I20,'DADES VOLUMS'!$A$3:$J$1005,9,FALSE),VLOOKUP(I20,'DADES VOLUMS'!$A$3:$J$1005,9,FALSE),L20),"") -> 0 | N20: =IFERROR(K20*M20/L20,"") | O20: =IFERROR(N20*VLOOKUP(I20,'DADES VOLUMS'!$A$3:$J$1005,6,FALSE),"") | P20: =IFERROR(O20*VLOOKUP(I20,'DADES VOLUMS'!$A$3:$J$1005,8,FALSE),"") | Q20: =IFERROR(C20/P20/5400,"")
A21: 189/21 | B21: 5-231131-613 | C21: 120000 | D21: 261 | E21: 177 | F21: 15 | G21: 0.19368 | H21: =F21*E21*D21 -> 692955 | I21: Màquina perclor ( VAIOC ) | J21: 0.7 | K21: =IFERROR((VLOOKUP(I21,'DADES VOLUMS'!$A$3:$J$1005,5,FALSE))/('CÀLCUL QUANTITATS VOLUM'!H21)*('CÀLCUL QUANTITATS VOLUM'!J21),"") -> 181.82999 | L21: =IFERROR(G21*K21*VLOOKUP(I21,'DADES VOLUMS'!$A$3:$J$1005,6,FALSE),"") -> 35.216832 | M21: =IFERROR(IF(L21>VLOOKUP(I21,'DADES VOLUMS'!$A$3:$J$1005,9,FALSE),VLOOKUP(I21,'DADES VOLUMS'!$A$3:$J$1005,9,FALSE),L21),"") -> 35.216832 | N21: =IFERROR(K21*M21/L21,"") -> 181.82999 | O21: =IFERROR(N21*VLOOKUP(I21,'DADES VOLUMS'!$A$3:$J$1005,6,FALSE),"") -> 181.82999 | P21: =IFERROR(O21*VLOOKUP(I21,'DADES VOLUMS'!$A$3:$J$1005,8,FALSE),"") -> 909.14994 | Q21: =IFERROR(C21/P21/5400,"") -> 0.024442857
A22: 189/21 | B22: 5-231131-611 | C22: 120000 | D22: 310 | E22: 200 | F22: 26 | G22: 0.37787 | H22: =F22*E22*D22 -> 1612000 | I22: Màquina perclor ( VAIOC ) | J22: 0.7 | K22: =IFERROR((VLOOKUP(I22,'DADES VOLUMS'!$A$3:$J$1005,5,FALSE))/('CÀLCUL QUANTITATS VOLUM'!H22)*('CÀLCUL QUANTITATS VOLUM'!J22),"") -> 78.163772 | L22: =IFERROR(G22*K22*VLOOKUP(I22,'DADES VOLUMS'!$A$3:$J$1005,6,FALSE),"") -> 29.535744 | M22: =IFERROR(IF(L22>VLOOKUP(I22,'DADES VOLUMS'!$A$3:$J$1005,9,FALSE),VLOOKUP(I22,'DADES VOLUMS'!$A$3:$J$1005,9,FALSE),L22),"") -> 29.535744 | N22: =IFERROR(K22*M22/L22,"") -> 78.163772 | O22: =IFERROR(N22*VLOOKUP(I22,'DADES VOLUMS'!$A$3:$J$1005,6,FALSE),"") -> 78.163772 | P22: =IFERROR(O22*VLOOKUP(I22,'DADES VOLUMS'!$A$3:$J$1005,8,FALSE),"") -> 390.81886 | Q22: =IFERROR(C22/P22/5400,"") -> 0.05686067
A23: 188/21 | B23: X657889500A-00-01 | C23: 150000 | D23: 168 | E23: 66 | F23: 17 | G23: 0.09921 | H23: =F23*E23*D23 -> 188496 | I23: Màquina perclor ( VAIOC ) | J23: 0.7 | K23: =IFERROR((VLOOKUP(I23,'DADES VOLUMS'!$A$3:$J$1005,5,FALSE))/('CÀLCUL QUANTITATS VOLUM'!H23)*('CÀLCUL QUANTITATS VOLUM'!J23),"") -> 668.4492 | L23: =IFERROR(G23*K23*VLOOKUP(I23,'DADES VOLUMS'!$A$3:$J$1005,6,FALSE),"") -> 66.316845 | M23: =IFERROR(IF(L23>VLOOKUP(I23,'DADES VOLUMS'!$A$3:$J$1005,9,FALSE),VLOOKUP(I23,'DADES VOLUMS'!$A$3:$J$1005,9,FALSE),L23),"") -> 66.316845 | N23: =IFERROR(K23*M23/L23,"") -> 668.4492 | O23: =IFERROR(N23*VLOOKUP(I23,'DADES VOLUMS'!$A$3:$J$1005,6,FALSE),"") -> 668.4492 | P23: =IFERROR(O23*VLOOKUP(I23,'DADES VOLUMS'!$A$3:$J$1005,8,FALSE),"") -> 3342.246 | Q23: =IFERROR(C23/P23/5400,"") -> 0.0083111111
A24: 250/21 | B24: 6487569 | C24: 218262 | D24: 155 | E24: 55 | F24: 75 | G24: 0.091 | H24: =F24*E24*D24 -> 639375 | I24: Màquina perclor ( VAIOC ) | J24: 0.7 | K24: =IFERROR((VLOOKUP(I24,'DADES VOLUMS'!$A$3:$J$1005,5,FALSE))/('CÀLCUL QUANTITATS VOLUM'!H24)*('CÀLCUL QUANTITATS VOLUM'!J24),"") -> 197.06745 | L24: =IFERROR(G24*K24*VLOOKUP(I24,'DADES VOLUMS'!$A$3:$J$1005,6,FALSE),"") -> 17.933138 | M24: =IFERROR(IF(L24>VLOOKUP(I24,'DADES VOLUMS'!$A$3:$J$1005,9,FALSE),VLOOKUP(I24,'DADES VOLUMS'!$A$3:$J$1005,9,FALSE),L24),"") -> 17.933138 | N24: =IFERROR(K24*M24/L24,"") -> 197.06745 | O24: =IFERROR(N24*VLOOKUP(I24,'DADES VOLUMS'!$A$3:$J$1005,6,FALSE),"") -> 197.06745 | P24: =IFERROR(O24*VLOOKUP(I24,'DADES VOLUMS'!$A$3:$J$1005,8,FALSE),"") -> 985.33724 | Q24: =IFERROR(C24/P24/5400,"") -> 0.04102036
A25: 253/21 | B25: 6538785 | C25: 300000 | D25: 149 | E25: 59 | F25: 30 | G25: 0.09514 | H25: =F25*E25*D25 -> 263730 | I25: Màquina perclor ( VAIOC ) | J25: 0.7 | K25: =IFERROR((VLOOKUP(I25,'DADES VOLUMS'!$A$3:$J$1005,5,FALSE))/('CÀLCUL QUANTITATS VOLUM'!H25)*('CÀLCUL QUANTITATS VOLUM'!J25),"") -> 477.76135 | L25: =IFERROR(G25*K25*VLOOKUP(I25,'DADES VOLUMS'!$A$3:$J$1005,6,FALSE),"") -> 45.454215 | M25: =IFERROR(IF(L25>VLOOKUP(I25,'DADES VOLUMS'!$A$3:$J$1005,9,FALSE),VLOOKUP(I25,'DADES VOLUMS'!$A$3:$J$1005,9,FALSE),L25),"") -> 45.454215 | N25: =IFERROR(K25*M25/L25,"") -> 477.76135 | O25: =IFERROR(N25*VLOOKUP(I25,'DADES VOLUMS'!$A$3:$J$1005,6,FALSE),"") -> 477.76135 | P25: =IFERROR(O25*VLOOKUP(I25,'DADES VOLUMS'!$A$3:$J$1005,8,FALSE),"") -> 2388.8067 | Q25: =IFERROR(C25/P25/5400,"") -> 0.023256614
A26: 255/21 | B26: X6557446 / X6557447 | C26: 110000 | D26: 149 | E26: 59 | F26: 37 | G26: 0.09951 | H26: =F26*E26*D26 -> 325267 | I26: Màquina perclor ( VAIOC ) | J26: 0.7 | K26: =IFERROR((VLOOKUP(I26,'DADES VOLUMS'!$A$3:$J$1005,5,FALSE))/('CÀLCUL QUANTITATS VOLUM'!H26)*('CÀLCUL QUANTITATS VOLUM'!J26),"") -> 387.37406 | L26: =IFERROR(G26*K26*VLOOKUP(I26,'DADES VOLUMS'!$A$3:$J$1005,6,FALSE),"") -> 38.547593 | M26: =IFERROR(IF(L26>VLOOKUP(I26,'DADES VOLUMS'!$A$3:$J$1005,9,FALSE),VLOOKUP(I26,'DADES VOLUMS'!$A$3:$J$1005,9,FALSE),L26),"") -> 38.547593 | N26: =IFERROR(K26*M26/L26,"") -> 387.37406 | O26: =IFERROR(N26*VLOOKUP(I26,'DADES VOLUMS'!$A$3:$J$1005,6,FALSE),"") -> 387.37406 | P26: =IFERROR(O26*VLOOKUP(I26,'DADES VOLUMS'!$A$3:$J$1005,8,FALSE),"") -> 1936.8703 | Q26: =IFERROR(C26/P26/5400,"") -> 0.010517158
A27: 267/21 | B27: 3428 5800 B | C27: 1000000 | D27: 190 | E27: 77 | F27: 60 | G27: 0.337 | H27: =F27*E27*D27 -> 877800 | I27: Màquina perclor ( VAIOC ) | J27: 0.7 | K27: =IFERROR((VLOOKUP(I27,'DADES VOLUMS'!$A$3:$J$1005,5,FALSE))/('CÀLCUL QUANTITATS VOLUM'!H27)*('CÀLCUL QUANTITATS VOLUM'!J27),"") -> 143.54067 | L27: =IFERROR(G27*K27*VLOOKUP(I27,'DADES VOLUMS'!$A$3:$J$1005,6,FALSE),"") -> 48.373206 | M27: =IFERROR(IF(L27>VLOOKUP(I27,'DADES VOLUMS'!$A$3:$J$1005,9,FALSE),VLOOKUP(I27,'DADES VOLUMS'!$A$3:$J$1005,9,FALSE),L27),"") -> 48.373206 | N27: =IFERROR(K27*M27/L27,"") -> 143.54067 | O27: =IFERROR(N27*VLOOKUP(I27,'DADES VOLUMS'!$A$3:$J$1005,6,FALSE),"") -> 143.54067 | P27: =IFERROR(O27*VLOOKUP(I27,'DADES VOLUMS'!$A$3:$J$1005,8,FALSE),"") -> 717.70335 | Q27: =IFERROR(C27/P27/5400,"") -> 0.25802469
A28: 250/21 ( Rev.1 ) | B28: 6487569 | C28: 218262 | D28: 155 | E28: 55 | F28: 75 | G28: 0.091 | H28: =F28*E28*D28 -> 639375 | I28: Màquina perclor ( VAIOC ) | J28: 0.7 | K28: =IFERROR((VLOOKUP(I28,'DADES VOLUMS'!$A$3:$J$1005,5,FALSE))/('CÀLCUL QUANTITATS VOLUM'!H28)*('CÀLCUL QUANTITATS VOLUM'!J28),"") -> 197.06745 | L28: =IFERROR(G28*K28*VLOOKUP(I28,'DADES VOLUMS'!$A$3:$J$1005,6,FALSE),"") -> 17.933138 | M28: =IFERROR(IF(L28>VLOOKUP(I28,'DADES VOLUMS'!$A$3:$J$1005,9,FALSE),VLOOKUP(I28,'DADES VOLUMS'!$A$3:$J$1005,9,FALSE),L28),"") -> 17.933138 | N28: =IFERROR(K28*M28/L28,"") -> 197.06745 | O28: =IFERROR(N28*VLOOKUP(I28,'DADES VOLUMS'!$A$3:$J$1005,6,FALSE),"") -> 197.06745 | P28: =IFERROR(O28*VLOOKUP(I28,'DADES VOLUMS'!$A$3:$J$1005,8,FALSE),"") -> 985.33724 | Q28: =IFERROR(C28/P28/5400,"") -> 0.04102036
A29: 330/21 | B29: 6002213 | C29: 166586 | D29: 82 | E29: 82 | F29: 26.8 | G29: 0.06375 | H29: =F29*E29*D29 -> 180203.2 | I29: Màquina perclor ( VAIOC ) | J29: 0.7 | K29: =IFERROR((VLOOKUP(I29,'DADES VOLUMS'!$A$3:$J$1005,5,FALSE))/('CÀLCUL QUANTITATS VOLUM'!H29)*('CÀLCUL QUANTITATS VOLUM'!J29),"") -> 699.21067 | L29: =IFERROR(G29*K29*VLOOKUP(I29,'DADES VOLUMS'!$A$3:$J$1005,6,FALSE),"") -> 44.57468 | M29: =IFERROR(IF(L29>VLOOKUP(I29,'DADES VOLUMS'!$A$3:$J$1005,9,FALSE),VLOOKUP(I29,'DADES VOLUMS'!$A$3:$J$1005,9,FALSE),L29),"") -> 44.57468 | N29: =IFERROR(K29*M29/L29,"") -> 699.21067 | O29: =IFERROR(N29*VLOOKUP(I29,'DADES VOLUMS'!$A$3:$J$1005,6,FALSE),"") -> 699.21067 | P29: =IFERROR(O29*VLOOKUP(I29,'DADES VOLUMS'!$A$3:$J$1005,8,FALSE),"") -> 3496.0533 | Q29: =IFERROR(C29/P29/5400,"") -> 0.0088240242
A30: 350/21 | B30: 38268826 | C30: 36000 | D30: 165 | E30: 92 | F30: 48 | G30: 0.1038 | H30: =F30*E30*D30 -> 728640 | I30: Màquina perclor ( VAIOC ) | J30: 0.7 | K30: =IFERROR((VLOOKUP(I30,'DADES VOLUMS'!$A$3:$J$1005,5,FALSE))/('CÀLCUL QUANTITATS VOLUM'!H30)*('CÀLCUL QUANTITATS VOLUM'!J30),"") -> 172.9249 | L30: =IFERROR(G30*K30*VLOOKUP(I30,'DADES VOLUMS'!$A$3:$J$1005,6,FALSE),"") -> 17.949605 | M30: =IFERROR(IF(L30>VLOOKUP(I30,'DADES VOLUMS'!$A$3:$J$1005,9,FALSE),VLOOKUP(I30,'DADES VOLUMS'!$A$3:$J$1005,9,FALSE),L30),"") -> 17.949605 | N30: =IFERROR(K30*M30/L30,"") -> 172.9249 | O30: =IFERROR(N30*VLOOKUP(I30,'DADES VOLUMS'!$A$3:$J$1005,6,FALSE),"") -> 172.9249 | P30: =IFERROR(O30*VLOOKUP(I30,'DADES VOLUMS'!$A$3:$J$1005,8,FALSE),"") -> 864.62451 | Q30: =IFERROR(C30/P30/5400,"") -> 0.0077104762
A31: 350/21 | B31: 38298095 | C31: 60000 | D31: 123 | E31: 128 | F31: 17 | G31: 0.0709 | H31: =F31*E31*D31 -> 267648 | I31: Màquina perclor ( VAIOC ) | J31: 0.7 | K31: =IFERROR((VLOOKUP(I31,'DADES VOLUMS'!$A$3:$J$1005,5,FALSE))/('CÀLCUL QUANTITATS VOLUM'!H31)*('CÀLCUL QUANTITATS VOLUM'!J31),"") -> 470.76758 | L31: =IFERROR(G31*K31*VLOOKUP(I31,'DADES VOLUMS'!$A$3:$J$1005,6,FALSE),"") -> 33.377421 | M31: =IFERROR(IF(L31>VLOOKUP(I31,'DADES VOLUMS'!$A$3:$J$1005,9,FALSE),VLOOKUP(I31,'DADES VOLUMS'!$A$3:$J$1005,9,FALSE),L31),"") -> 33.377421 | N31: =IFERROR(K31*M31/L31,"") -> 470.76758 | O31: =IFERROR(N31*VLOOKUP(I31,'DADES VOLUMS'!$A$3:$J$1005,6,FALSE),"") -> 470.76758 | P31: =IFERROR(O31*VLOOKUP(I31,'DADES VOLUMS'!$A$3:$J$1005,8,FALSE),"") -> 2353.8379 | Q31: =IFERROR(C31/P31/5400,"") -> 0.0047204233
A32: 344/21 | B32: 6347198 002 | C32: 49000 | D32: 191 | E32: 92 | F32: 75 | G32: 0.2675 | H32: =F32*E32*D32 -> 1317900 | I32: Màquina perclor ( VAIOC ) | J32: 0.7 | K32: =IFERROR((VLOOKUP(I32,'DADES VOLUMS'!$A$3:$J$1005,5,FALSE))/('CÀLCUL QUANTITATS VOLUM'!H32)*('CÀLCUL QUANTITATS VOLUM'!J32),"") -> 95.606647 | L32: =IFERROR(G32*K32*VLOOKUP(I32,'DADES VOLUMS'!$A$3:$J$1005,6,FALSE),"") -> 25.574778 | M32: =IFERROR(IF(L32>VLOOKUP(I32,'DADES VOLUMS'!$A$3:$J$1005,9,FALSE),VLOOKUP(I32,'DADES VOLUMS'!$A$3:$J$1005,9,FALSE),L32),"") -> 25.574778 | N32: =IFERROR(K32*M32/L32,"") -> 95.606647 | O32: =IFERROR(N32*VLOOKUP(I32,'DADES VOLUMS'!$A$3:$J$1005,6,FALSE),"") -> 95.606647 | P32: =IFERROR(O32*VLOOKUP(I32,'DADES VOLUMS'!$A$3:$J$1005,8,FALSE),"") -> 478.03323 | Q32: =IFERROR(C32/P32/5400,"") -> 0.018982099
A33: 337/21 | B33: 3136916-AA0 | C33: 191500 | D33: 128 | E33: 90 | F33: 30 | G33: 0.1626 | H33: =F33*E33*D33 -> 345600 | I33: Màquina perclor ( VAIOC ) | J33: 0.7 | K33: =IFERROR((VLOOKUP(I33,'DADES VOLUMS'!$A$3:$J$1005,5,FALSE))/('CÀLCUL QUANTITATS VOLUM'!H33)*('CÀLCUL QUANTITATS VOLUM'!J33),"") -> 364.58333 | L33: =IFERROR(G33*K33*VLOOKUP(I33,'DADES VOLUMS'!$A$3:$J$1005,6,FALSE),"") -> 59.28125 | M33: =IFERROR(IF(L33>VLOOKUP(I33,'DADES VOLUMS'!$A$3:$J$1005,9,FALSE),VLOOKUP(I33,'DADES VOLUMS'!$A$3:$J$1005,9,FALSE),L33),"") -> 59.28125 | N33: =IFERROR(K33*M33/L33,"") -> 364.58333 | O33: =IFERROR(N33*VLOOKUP(I33,'DADES VOLUMS'!$A$3:$J$1005,6,FALSE),"") -> 364.58333 | P33: =IFERROR(O33*VLOOKUP(I33,'DADES VOLUMS'!$A$3:$J$1005,8,FALSE),"") -> 1822.9167 | Q33: =IFERROR(C33/P33/5400,"") -> 0.019453968
A34: 017/22 | B34: A022B337A | C34: 85000 | D34: 108 | E34: 80 | F34: 97 | G34: 0.19212 | H34: =F34*E34*D34 -> 838080 | I34: Màquina perclor ( VAIOC ) | J34: 0.85 | K34: =IFERROR((VLOOKUP(I34,'DADES VOLUMS'!$A$3:$J$1005,5,FALSE))/('CÀLCUL QUANTITATS VOLUM'!H34)*('CÀLCUL QUANTITATS VOLUM'!J34),"") -> 182.56014 | L34: =IFERROR(G34*K34*VLOOKUP(I34,'DADES VOLUMS'!$A$3:$J$1005,6,FALSE),"") -> 35.073454 | M34: =IFERROR(IF(L34>VLOOKUP(I34,'DADES VOLUMS'!$A$3:$J$1005,9,FALSE),VLOOKUP(I34,'DADES VOLUMS'!$A$3:$J$1005,9,FALSE),L34),"") -> 35.073454 | N34: =IFERROR(K34*M34/L34,"") -> 182.56014 | O34: =IFERROR(N34*VLOOKUP(I34,'DADES VOLUMS'!$A$3:$J$1005,6,FALSE),"") -> 182.56014 | P34: =IFERROR(O34*VLOOKUP(I34,'DADES VOLUMS'!$A$3:$J$1005,8,FALSE),"") -> 912.80069 | Q34: =IFERROR(C34/P34/5400,"") -> 0.017244444
A35: 005/22 | B35: 658063600_660632800 | C35: 1000000 | D35: 125 | E35: 55 | F35: 51 | G35: 0.078 | H35: =F35*E35*D35 -> 350625 | I35: Màquina perclor ( VAIOC ) | J35: 0.85 | K35: =IFERROR((VLOOKUP(I35,'DADES VOLUMS'!$A$3:$J$1005,5,FALSE))/('CÀLCUL QUANTITATS VOLUM'!H35)*('CÀLCUL QUANTITATS VOLUM'!J35),"") -> 436.36364 | L35: =IFERROR(G35*K35*VLOOKUP(I35,'DADES VOLUMS'!$A$3:$J$1005,6,FALSE),"") -> 34.036364 | M35: =IFERROR(IF(L35>VLOOKUP(I35,'DADES VOLUMS'!$A$3:$J$1005,9,FALSE),VLOOKUP(I35,'DADES VOLUMS'!$A$3:$J$1005,9,FALSE),L35),"") -> 34.036364 | N35: =IFERROR(K35*M35/L35,"") -> 436.36364 | O35: =IFERROR(N35*VLOOKUP(I35,'DADES VOLUMS'!$A$3:$J$1005,6,FALSE),"") -> 436.36364 | P35: =IFERROR(O35*VLOOKUP(I35,'DADES VOLUMS'!$A$3:$J$1005,8,FALSE),"") -> 2181.8182 | Q35: =IFERROR(C35/P35/5400,"") -> 0.084876543
A36: 071/22 | B36: A023F663 B00 | C36: 12999 | D36: 163 | E36: 99 | F36: 65 | G36: 0.3723 | H36: =F36*E36*D36 -> 1048905 | I36: Màquina perclor ( VAIOC ) | J36: 0.85 | K36: =IFERROR((VLOOKUP(I36,'DADES VOLUMS'!$A$3:$J$1005,5,FALSE))/('CÀLCUL QUANTITATS VOLUM'!H36)*('CÀLCUL QUANTITATS VOLUM'!J36),"") -> 145.8664 | L36: =IFERROR(G36*K36*VLOOKUP(I36,'DADES VOLUMS'!$A$3:$J$1005,6,FALSE),"") -> 54.306062 | M36: =IFERROR(IF(L36>VLOOKUP(I36,'DADES VOLUMS'!$A$3:$J$1005,9,FALSE),VLOOKUP(I36,'DADES VOLUMS'!$A$3:$J$1005,9,FALSE),L36),"") -> 54.306062 | N36: =IFERROR(K36*M36/L36,"") -> 145.8664 | O36: =IFERROR(N36*VLOOKUP(I36,'DADES VOLUMS'!$A$3:$J$1005,6,FALSE),"") -> 145.8664 | P36: =IFERROR(O36*VLOOKUP(I36,'DADES VOLUMS'!$A$3:$J$1005,8,FALSE),"") -> 729.33202 | Q36: =IFERROR(C36/P36/5400,"") -> 0.0033005849
A37: 108/22 | B37: 6604390 | C37: 615602 | D37: 155 | E37: 53 | F37: 51 | G37: 0.089498 | H37: =F37*E37*D37 -> 418965 | I37: Màquina perclor ( VAIOC ) | J37: 0.85 | K37: =IFERROR((VLOOKUP(I37,'DADES VOLUMS'!$A$3:$J$1005,5,FALSE))/('CÀLCUL QUANTITATS VOLUM'!H37)*('CÀLCUL QUANTITATS VOLUM'!J37),"") -> 365.18564 | L37: =IFERROR(G37*K37*VLOOKUP(I37,'DADES VOLUMS'!$A$3:$J$1005,6,FALSE),"") -> 32.683384 | M37: =IFERROR(IF(L37>VLOOKUP(I37,'DADES VOLUMS'!$A$3:$J$1005,9,FALSE),VLOOKUP(I37,'DADES VOLUMS'!$A$3:$J$1005,9,FALSE),L37),"") -> 32.683384 | N37: =IFERROR(K37*M37/L37,"") -> 365.18564 | O37: =IFERROR(N37*VLOOKUP(I37,'DADES VOLUMS'!$A$3:$J$1005,6,FALSE),"") -> 365.18564 | P37: =IFERROR(O37*VLOOKUP(I37,'DADES VOLUMS'!$A$3:$J$1005,8,FALSE),"") -> 1825.9282 | Q37: =IFERROR(C37/P37/5400,"") -> 0.062434203
A38: 135/22 | B38: A0053Y5698A | C38: 299950 | D38: 99 | E38: 76 | F38: 43 | G38: 0.11169 | H38: =F38*E38*D38 -> 323532 | I38: Màquina perclor ( VAIOC ) | J38: 0.7 | K38: =IFERROR((VLOOKUP(I38,'DADES VOLUMS'!$A$3:$J$1005,5,FALSE))/('CÀLCUL QUANTITATS VOLUM'!H38)*('CÀLCUL QUANTITATS VOLUM'!J38),"") -> 389.45143 | L38: =IFERROR(G38*K38*VLOOKUP(I38,'DADES VOLUMS'!$A$3:$J$1005,6,FALSE),"") -> 43.49783 | M38: =IFERROR(IF(L38>VLOOKUP(I38,'DADES VOLUMS'!$A$3:$J$1005,9,FALSE),VLOOKUP(I38,'DADES VOLUMS'!$A$3:$J$1005,9,FALSE),L38),"") -> 43.49783 | N38: =IFERROR(K38*M38/L38,"") -> 389.45143 | O38: =IFERROR(N38*VLOOKUP(I38,'DADES VOLUMS'!$A$3:$J$1005,6,FALSE),"") -> 389.45143 | P38: =IFERROR(O38*VLOOKUP(I38,'DADES VOLUMS'!$A$3:$J$1005,8,FALSE),"") -> 1947.2571 | Q38: =IFERROR(C38/P38/5400,"") -> 0.028525404
A39: 121/22 | B39: 3138417-1 | C39: 42000 | D39: 217 | E39: 106 | F39: 50 | G39: 0.3068 | H39: =F39*E39*D39 -> 1150100 | I39: Màquina perclor ( VAIOC ) | J39: 0.85 | K39: =IFERROR((VLOOKUP(I39,'DADES VOLUMS'!$A$3:$J$1005,5,FALSE))/('CÀLCUL QUANTITATS VOLUM'!H39)*('CÀLCUL QUANTITATS VOLUM'!J39),"") -> 133.03191 | L39: =IFERROR(G39*K39*VLOOKUP(I39,'DADES VOLUMS'!$A$3:$J$1005,6,FALSE),"") -> 40.81419 | M39: =IFERROR(IF(L39>VLOOKUP(I39,'DADES VOLUMS'!$A$3:$J$1005,9,FALSE),VLOOKUP(I39,'DADES VOLUMS'!$A$3:$J$1005,9,FALSE),L39),"") -> 40.81419 | N39: =IFERROR(K39*M39/L39,"") -> 133.03191 | O39: =IFERROR(N39*VLOOKUP(I39,'DADES VOLUMS'!$A$3:$J$1005,6,FALSE),"") -> 133.03191 | P39: =IFERROR(O39*VLOOKUP(I39,'DADES VOLUMS'!$A$3:$J$1005,8,FALSE),"") -> 665.15955 | Q39: =IFERROR(C39/P39/5400,"") -> 0.011693101
A40: 135/22 | B40: A0053Y5698A | C40: 300000 | D40: 99 | E40: 76 | F40: 43 | G40: 0.11449 | H40: =F40*E40*D40 -> 323532 | I40: Màquina perclor ( VAIOC ) | J40: 0.7 | K40: =IFERROR((VLOOKUP(I40,'DADES VOLUMS'!$A$3:$J$1005,5,FALSE))/('CÀLCUL QUANTITATS VOLUM'!H40)*('CÀLCUL QUANTITATS VOLUM'!J40),"") -> 389.45143 | L40: =IFERROR(G40*K40*VLOOKUP(I40,'DADES VOLUMS'!$A$3:$J$1005,6,FALSE),"") -> 44.588294 | M40: =IFERROR(IF(L40>VLOOKUP(I40,'DADES VOLUMS'!$A$3:$J$1005,9,FALSE),VLOOKUP(I40,'DADES VOLUMS'!$A$3:$J$1005,9,FALSE),L40),"") -> 44.588294 | N40: =IFERROR(K40*M40/L40,"") -> 389.45143 | O40: =IFERROR(N40*VLOOKUP(I40,'DADES VOLUMS'!$A$3:$J$1005,6,FALSE),"") -> 389.45143 | P40: =IFERROR(O40*VLOOKUP(I40,'DADES VOLUMS'!$A$3:$J$1005,8,FALSE),"") -> 1947.2571 | Q40: =IFERROR(C40/P40/5400,"") -> 0.028530159
A41: 177/22 | B41: H18326-050 | C41: 126000 | D41: 167 | E41: 47 | F41: 34 | G41: 0.05765 | H41: =F41*E41*D41 -> 266866 | I41: Màquina perclor ( VAIOC ) | J41: 0.7 | K41: =IFERROR((VLOOKUP(I41,'DADES VOLUMS'!$A$3:$J$1005,5,FALSE))/('CÀLCUL QUANTITATS VOLUM'!H41)*('CÀLCUL QUANTITATS VOLUM'!J41),"") -> 472.14707 | L41: =IFERROR(G41*K41*VLOOKUP(I41,'DADES VOLUMS'!$A$3:$J$1005,6,FALSE),"") -> 27.219279 | M41: =IFERROR(IF(L41>VLOOKUP(I41,'DADES VOLUMS'!$A$3:$J$1005,9,FALSE),VLOOKUP(I41,'DADES VOLUMS'!$A$3:$J$1005,9,FALSE),L41),"") -> 27.219279 | N41: =IFERROR(K41*M41/L41,"") -> 472.14707 | O41: =IFERROR(N41*VLOOKUP(I41,'DADES VOLUMS'!$A$3:$J$1005,6,FALSE),"") -> 472.14707 | P41: =IFERROR(O41*VLOOKUP(I41,'DADES VOLUMS'!$A$3:$J$1005,8,FALSE),"") -> 2360.7354 | Q41: =IFERROR(C41/P41/5400,"") -> 0.0098839259
A42: 177/22 | B42: H18324-050 | C42: 126000 | D42: 112 | E42: 53 | F42: 26 | G42: 0.03582 | H42: =F42*E42*D42 -> 154336 | I42: Màquina perclor ( VAIOC ) | J42: 0.7 | K42: =IFERROR((VLOOKUP(I42,'DADES VOLUMS'!$A$3:$J$1005,5,FALSE))/('CÀLCUL QUANTITATS VOLUM'!H42)*('CÀLCUL QUANTITATS VOLUM'!J42),"") -> 816.40058 | L42: =IFERROR(G42*K42*VLOOKUP(I42,'DADES VOLUMS'!$A$3:$J$1005,6,FALSE),"") -> 29.243469 | M42: =IFERROR(IF(L42>VLOOKUP(I42,'DADES VOLUMS'!$A$3:$J$1005,9,FALSE),VLOOKUP(I42,'DADES VOLUMS'!$A$3:$J$1005,9,FALSE),L42),"") -> 29.243469 | N42: =IFERROR(K42*M42/L42,"") -> 816.40058 | O42: =IFERROR(N42*VLOOKUP(I42,'DADES VOLUMS'!$A$3:$J$1005,6,FALSE),"") -> 816.40058 | P42: =IFERROR(O42*VLOOKUP(I42,'DADES VOLUMS'!$A$3:$J$1005,8,FALSE),"") -> 4082.0029 | Q42: =IFERROR(C42/P42/5400,"") -> 0.0057161481
A43: 177/22 | B43: H18328-050 | C43: 126000 | D43: 307 | E43: 183 | F43: 51 | G43: 0.18939 | H43: =F43*E43*D43 -> 2865231 | I43: Màquina perclor ( VAIOC ) | J43: 0.8 | K43: =IFERROR((VLOOKUP(I43,'DADES VOLUMS'!$A$3:$J$1005,5,FALSE))/('CÀLCUL QUANTITATS VOLUM'!H43)*('CÀLCUL QUANTITATS VOLUM'!J43),"") -> 50.257728 | L43: =IFERROR(G43*K43*VLOOKUP(I43,'DADES VOLUMS'!$A$3:$J$1005,6,FALSE),"") -> 9.5183111 | M43: =IFERROR(IF(L43>VLOOKUP(I43,'DADES VOLUMS'!$A$3:$J$1005,9,FALSE),VLOOKUP(I43,'DADES VOLUMS'!$A$3:$J$1005,9,FALSE),L43),"") -> 9.5183111 | N43: =IFERROR(K43*M43/L43,"") -> 50.257728 | O43: =IFERROR(N43*VLOOKUP(I43,'DADES VOLUMS'!$A$3:$J$1005,6,FALSE),"") -> 50.257728 | P43: =IFERROR(O43*VLOOKUP(I43,'DADES VOLUMS'!$A$3:$J$1005,8,FALSE),"") -> 251.28864 | Q43: =IFERROR(C43/P43/5400,"") -> 0.092854708
A44: 137/22 | B44: X6598634-00 | C44: 1700 | D44: 223 | E44: 107 | F44: 42 | G44: 0.12255 | H44: =F44*E44*D44 -> 1002162 | I44: Màquina perclor ( VAIOC ) | J44: 0.8 | K44: =IFERROR((VLOOKUP(I44,'DADES VOLUMS'!$A$3:$J$1005,5,FALSE))/('CÀLCUL QUANTITATS VOLUM'!H44)*('CÀLCUL QUANTITATS VOLUM'!J44),"") -> 143.68934 | L44: =IFERROR(G44*K44*VLOOKUP(I44,'DADES VOLUMS'!$A$3:$J$1005,6,FALSE),"") -> 17.609129 | M44: =IFERROR(IF(L44>VLOOKUP(I44,'DADES VOLUMS'!$A$3:$J$1005,9,FALSE),VLOOKUP(I44,'DADES VOLUMS'!$A$3:$J$1005,9,FALSE),L44),"") -> 17.609129 | N44: =IFERROR(K44*M44/L44,"") -> 143.68934 | O44: =IFERROR(N44*VLOOKUP(I44,'DADES VOLUMS'!$A$3:$J$1005,6,FALSE),"") -> 143.68934 | P44: =IFERROR(O44*VLOOKUP(I44,'DADES VOLUMS'!$A$3:$J$1005,8,FALSE),"") -> 718.44672 | Q44: =IFERROR(C44/P44/5400,"") -> 0.00043818812
A45: 142/22 | B45: 3100585 AA2 | C45: 191000 | D45: 217 | E45: 20 | F45: 26 | G45: 0.05408 | H45: =F45*E45*D45 -> 112840 | I45: Màquina perclor ( VAIOC ) | J45: 0.75 | K45: =IFERROR((VLOOKUP(I45,'DADES VOLUMS'!$A$3:$J$1005,5,FALSE))/('CÀLCUL QUANTITATS VOLUM'!H45)*('CÀLCUL QUANTITATS VOLUM'!J45),"") -> 1196.3843 | L45: =IFERROR(G45*K45*VLOOKUP(I45,'DADES VOLUMS'!$A$3:$J$1005,6,FALSE),"") -> 64.700461 | M45: =IFERROR(IF(L45>VLOOKUP(I45,'DADES VOLUMS'!$A$3:$J$1005,9,FALSE),VLOOKUP(I45,'DADES VOLUMS'!$A$3:$J$1005,9,FALSE),L45),"") -> 64.700461 | N45: =IFERROR(K45*M45/L45,"") -> 1196.3843 | O45: =IFERROR(N45*VLOOKUP(I45,'DADES VOLUMS'!$A$3:$J$1005,6,FALSE),"") -> 1196.3843 | P45: =IFERROR(O45*VLOOKUP(I45,'DADES VOLUMS'!$A$3:$J$1005,8,FALSE),"") -> 5981.9213 | Q45: =IFERROR(C45/P45/5400,"") -> 0.0059128779
...

Sheet Recollida dades VAIOC
B1: RECOLLIDA DADES DESENGREIX VAIOC
B2: Referència | C2: Quantitat gàbia | D2: Programa | E2: Temps cicle (min) | F2: Foto (X) | G2: Comentari
B3: 51006612 | C3: 350
B4: 51006731 | C4: 600
B5: 51006224
B39: *Avisar a preparador per fer foto de la gàbia plena. Servirà per crear les especificacions de preparació.

Sheet PLANTILLA
B2: DADES PEÇA | M2: Màquina
B3: INFO COMERCIAL | E3: CARACTERÍSTIQUES FÍSIQUES PEÇA | M3: Màquina neteja partícules
B4: Oferta | C4: Ref | D4: Volum anual | E4: a(mm) | F4: b(mm) | G4: h(mm) | H4: Pes net peça (kg) | I4: V(mm3) | J4: Coef. Seguretat
B5: 298/232 | C5: A0057D0650 | D5: 400000 | E5: 244 | F5: 180 | G5: 10 | H5: 0.09 | I5: =E5*F5*G5 -> 439200 | J5: 0.7
C7: REQUERIMENTS PEÇA | E7: PRESTACIONS MÀQUINA | K7: PRODUCTIVITAT
B8: DESENGREIX (N·m-1) | K8: Prod/h real | L8: Càrrega màquina
B9: Tensió superficial | C9: 32 | E9: 38 | G9: =IF(C9<E9, "FACTIBLE", "NO FACTIBLE") -> FACTIBLE | K9: =IFERROR(VLOOKUP(PLANTILLA!$M$3,'DADES VOLUMS'!$A$3:$J$1005,9,FALSE)/(PLANTILLA!I5/J5),"ERROR") -> 0 | L9: =IFERROR(D5/K9/5400,"")
B11: NETEJA | C11: Important mantenir un baix nivell de rebava a la peça o matar canto, principal font de generació de partícules.
B12: Mida partícula (µm)
A13: H | B13: Hard Metallic | C13: 400 | E13: 399 | G13: =IF(C13>E13, "FACTIBLE", "NO FACTIBLE") -> FACTIBLE | I13: =IF(G13="NO FACTIBLE","",IF(C13<250, "CAL COL·LOCAR LES PECES BÉ A LA GÀBIA", "ES POT NETEJAR A BULK" )) -> ES POT NETEJAR A BULK
A14: I | B14: Hard Non-Metallic | C14: 600 | E14: 399 | G14: =IF(C14>E14, "FACTIBLE", "NO FACTIBLE") -> FACTIBLE | I14: =IF(C14<250, "CAL COL·LOCAR LES PECES BÉ A LA GÀBIA", "ES POT NETEJAR A BULK" ) -> ES POT NETEJAR A BULK
A15: J | B15: Fibres | C15: 1000 | E15: 499 | G15: =IF(C15>E15, "FACTIBLE", "NO FACTIBLE") -> FACTIBLE | I15: =IF(G15="NO FACTIBLE","",IF(C15<500, "REQUEREIX DE SALA GRIS",""))
B16: Gravimetria
B17: Residu en mg/100g | C17: 2 | G17: =IF(C17>E17, "FACTIBLE", "NO FACTIBLE") -> FACTIBLE
B19: Una peça pot quedar encapsulada dins d'una altre? (SI/NO) | G19: NO | H19: =IF(G19="SI","CAL COL·LOCAR LES PECES BÉ A LA GÀBIA","")
B21: OLIAT
B22: SI/NO | C22: NO | E22: SI | G22: =IF(E22="si","FACTIBLE",IF(C22="SI","NO FACTIBLE","FACTIBLE")) -> FACTIBLE

Sheet DADES VOLUMS
K1: N·m-1 | L1: Mida partícula (µm) | O1: Gravimetria | P1: Oliat
B2: a(mm) | C2: b(mm) | D2: h(mm) | E2: V gàbia(mm3) | F2: Nºgàbies | G2: V cicle (mm3) | H2: Nºcicles/h | I2: V/h (mm3) | J2: Capacitat en kg | K2: Tensió superficial | L2: Hard Metallic | M2: Hard Non-Metallic | N2: Fibres | O2: Residu en mg/100g peça | P2: SI/NO | Q2: Revisió
A3: Màquina neteja partícules | B3: 300 | C3: 450 | D3: 275 | E3: =B3*C3*D3 -> 37125000 | F3: 2 | G3: =E3*F3 -> 74250000 | H3: 3 | J3: 200 | Q3: 44274
A4: Màquina neteja partícules gran | B4: 300 | C4: 450 | D4: 275 | E4: =B4*C4*D4 -> 37125000 | F4: 4 | G4: =E4*F4 -> 148500000 | H4: 3 | J4: 200
A5: Màquina perclor ( VAIOC ) | B5: 1000 | C5: 450 | D5: 400 | E5: =B5*C5*D5 -> 180000000 | F5: 1 | G5: =E5*F5 -> 180000000 | H5: 5 | I5: =G5*H5 -> 900000000 | J5: 60 | L5: 400 | N5: 500
A6: KPM 800 MAX - Desengreix | B6: 600 | C6: 400 | D6: 400 | E6: =B6*C6*D6 -> 96000000 | F6: 3 | G6: =E6*F6 -> 288000000 | H6: 4 | I6: =G6*H6 -> 1152000000 | J6: 100000000
A7: KPM 800 MAX - Neteja partícules | B7: 600 | C7: 400 | D7: 400 | E7: =B7*C7*D7 -> 96000000 | F7: 3 | G7: =E7*F7 -> 288000000 | H7: 2.5 | I7: =G7*H7 -> 720000000 | J7: 100000000 | K7: 38 | L7: 400 | M7: 400 | N7: 500 | O7: 0.2 | P7: SI
A8: KPM 800 MAX - Oliat | B8: 600 | C8: 400 | D8: 400 | E8: =B8*C8*D8 -> 96000000 | F8: 3 | G8: =E8*F8 -> 288000000 | H8: 3 | I8: =G8*H8 -> 864000000 | J8: 100000000
A9: Màquina S525 | B9: 300 | C9: 450 | D9: 150 | E9: =B9*C9*D9 -> 20250000 | F9: 4 | G9: =E9*F9 -> 81000000 | H9: 4 | J9: 30
A10: Màquina KSW | E10: =B10*C10*D10 -> 0
A11: 181 | B11: 255 | C11: 185 | D11: 164 | E11: =B11*C11*D11 -> 7736700 | F11: 1 | J11: 10
A12: 184 | B12: 595 | C12: 395 | D12: 145 | E12: =B12*C12*D12 -> 34078625 | F12: 1 | J12: 10
A13: 185 | B13: 590 | C13: 390 | D13: 300 | E13: =B13*C13*D13 -> 69030000 | F13: 1 | J13: 10
A14: B1 | B14: 600 | C14: 400 | D14: 210 | E14: =B14*C14*D14 -> 50400000 | F14: 1 | J14: 10
A15: B2 | B15: 390 | C15: 300 | D15: 120 | E15: =B15*C15*D15 -> 14040000 | F15: 1 | J15: 10
A16: B3 | B16: 300 | C16: 450 | D16: 100 | E16: =B16*C16*D16 -> 13500000 | F16: 1 | J16: 12
A17: Ref 1572 | B17: 385 | C17: 285 | D17: 190 | E17: =B17*C17*D17 -> 20847750 | F17: 1 | J17: 10
A18: Ref 2263 | B18: 385 | C18: 285 | D18: 150 | E18: =B18*C18*D18 -> 16458750 | F18: 1 | J18: 10
A19: Ref 2753 | B19: 385 | C19: 285 | D19: 95 | E19: =B19*C19*D19 -> 10423875 | F19: 1 | J19: 10
A20: Ref 3118 | B20: 590 | C20: 390 | D20: 150 | E20: =B20*C20*D20 -> 34515000 | F20: 1 | J20: 10
A21: Ref 3411 | B21: 385 | C21: 285 | D21: 80 | E21: =B21*C21*D21 -> 8778000 | F21: 1 | J21: 10
A22: Ref 3412 | B22: 390 | C22: 291 | D22: 90 | E22: =B22*C22*D22 -> 10214100 | F22: 1 | J22: 10
A23: Ref 3413 | B23: 385 | C23: 285 | D23: 150 | E23: =B23*C23*D23 -> 16458750 | F23: 1 | J23: 10
A24: Ref 3414 | B24: 390 | C24: 291 | D24: 210 | E24: =B24*C24*D24 -> 23832900 | F24: 1 | J24: 10
A25: Ref 3414 SOGEFI | B25: 385 | C25: 265 | D25: 190 | E25: =B25*C25*D25 -> 19384750 | F25: 1 | J25: 12
... A30: Heson | B30: 1000 | C30: 800 | D30: 500 | E30: =B30*C30*D30 -> 400000000 | F30: 1 | J30: 2000
A31: SAP | E31: =B31*C31*D31 -> 0
A32: Escandall SOME | E32: =B32*C32*D32 -> 0
E33: =B33*C33*D33 -> 0
E34: =B34*C34*D34 -> 0
E35: =B35*C35*D35 -> 0
E36: =B36*C36*D36 -> 0
E37: =B37*C37*D37 -> 0
E38: =B38*C38*D38 -> 0
E39: =B39*C39*D39 -> 0
E40: =B40*C40*D40 -> 0
E41: =B41*C41*D41 -> 0
E42: =B42*C42*D42 -> 0
E43: =B43*C43*D43 -> 0
E44: =B44*C44*D44 -> 0
...
